<sdf version='1.4'>
  <world name='default'>
    <light name='sun' type='directional'>
      <cast_shadows>1</cast_shadows>
      <pose>0 0 10 0 -0 0</pose>
      <diffuse>0.8 0.8 0.8 1</diffuse>
      <specular>0.2 0.2 0.2 1</specular>
      <attenuation>
        <range>1000</range>
        <constant>0.9</constant>
        <linear>0.01</linear>
        <quadratic>0.001</quadratic>
      </attenuation>
      <direction>-0.5 0.1 -0.9</direction>
    </light>
    <model name='ground_plane'>
      <static>1</static>
      <link name='link'>
        <collision name='collision'>
          <geometry>
            <plane>
              <normal>0 0 1</normal>
              <size>100 100</size>
            </plane>
          </geometry>
          <surface>
            <friction>
              <ode>
                <mu>100</mu>
                <mu2>50</mu2>
              </ode>
            </friction>
            <bounce/>
            <contact>
              <ode/>
            </contact>
          </surface>
          <max_contacts>10</max_contacts>
        </collision>
        <visual name='visual'>
          <cast_shadows>0</cast_shadows>
          <geometry>
            <plane>
              <normal>0 0 1</normal>
              <size>100 100</size>
            </plane>
          </geometry>
          <material>
            <script>
              <uri>file://media/materials/scripts/gazebo.material</uri>
              <name>Gazebo/Grey</name>
            </script>
          </material>
        </visual>
        <velocity_decay>
          <linear>0</linear>
          <angular>0</angular>
        </velocity_decay>
        <self_collide>0</self_collide>
        <kinematic>0</kinematic>
        <gravity>1</gravity>
      </link>
    </model>
    <physics type='ode'>
      <max_step_size>0.001</max_step_size>
      <real_time_factor>1</real_time_factor>
      <real_time_update_rate>1000</real_time_update_rate>
      <gravity>0 0 -9.8</gravity>
    </physics>
    <scene>
      <ambient>0.4 0.4 0.4 1</ambient>
      <background>0.7 0.7 0.7 1</background>
      <shadows>1</shadows>
    </scene>
    <spherical_coordinates>
      <surface_model>EARTH_WGS84</surface_model>
      <latitude_deg>0</latitude_deg>
      <longitude_deg>0</longitude_deg>
      <elevation>0</elevation>
      <heading_deg>0</heading_deg>
    </spherical_coordinates>
    <state world_name='default'>
      <sim_time>1905 547000000</sim_time>
      <real_time>76 404858473</real_time>
      <wall_time>1458313259 700369362</wall_time>
      <model name='drc_practice_blue_cylinder_1'>
        <pose>-2 2 0 0 -0 0</pose>
        <link name='link'>
          <pose>-2 2 0 0 -0 0</pose>
          <velocity>0 0 0 0 -0 0</velocity>
          <acceleration>0 0 0 0 -0 0</acceleration>
          <wrench>0 0 0 0 -0 0</wrench>
        </link>
      </model>
      <model name='drc_practice_blue_cylinder_2'>
        <pose>-2 -2 0 0 -0 0</pose>
        <link name='link'>
          <pose>-2 -2 0 0 -0 0</pose>
          <velocity>0 0 0 0 -0 0</velocity>
          <acceleration>0 0 0 0 -0 0</acceleration>
          <wrench>0 0 0 0 -0 0</wrench>
        </link>
      </model>
      <model name='drc_practice_blue_cylinder_3'>
        <pose>-5 -2 0 0 -0 0</pose>
        <link name='link'>
          <pose>-5 -2 0 0 -0 0</pose>
          <velocity>0 0 0 0 -0 0</velocity>
          <acceleration>0 0 0 0 -0 0</acceleration>
          <wrench>0 0 0 0 -0 0</wrench>
        </link>
      </model>
      <model name='drc_practice_blue_cylinder_4'>
        <pose>-5 2 0 0 -0 0</pose>
        <link name='link'>
          <pose>-5 2 0 0 -0 0</pose>
          <velocity>0 0 0 0 -0 0</velocity>
          <acceleration>0 0 0 0 -0 0</acceleration>
          <wrench>0 0 0 0 -0 0</wrench>
        </link>
      </model>
      <model name='drc_practice_blue_cylinder_5'>
        <pose>-8 -2 0 0 -0 0</pose>
        <link name='link'>
          <pose>-8 -2 0 0 -0 0</pose>
          <velocity>0 0 0 0 -0 0</velocity>
          <acceleration>0 0 0 0 -0 0</acceleration>
          <wrench>0 0 0 0 -0 0</wrench>
        </link>
      </model>
      <model name='drc_practice_blue_cylinder_6'>
        <pose>-8 2 0 0 -0 0</pose>
        <link name='link'>
          <pose>-8 2 0 0 -0 0</pose>
          <velocity>0 0 0 0 -0 0</velocity>
          <acceleration>0 0 0 0 -0 0</acceleration>
          <wrench>0 0 0 0 -0 0</wrench>
        </link>
      </model>
      <model name='drc_practice_blue_cylinder_7'>
        <pose>-8 6 0 0 -0 0</pose>
        <link name='link'>
          <pose>-8 6 0 0 -0 0</pose>
          <velocity>0 0 0 0 -0 0</velocity>
          <acceleration>0 0 0 0 -0 0</acceleration>
          <wrench>0 0 0 0 -0 0</wrench>
        </link>
      </model>
      <model name='drc_practice_blue_cylinder_8'>
        <pose>-5 6 0 0 -0 0</pose>
        <link name='link'>
          <pose>-5 6 0 0 -0 0</pose>
          <velocity>0 0 0 0 -0 0</velocity>
          <acceleration>0 0 0 0 -0 0</acceleration>
          <wrench>0 0 0 0 -0 0</wrench>
        </link>
      </model>
      <model name='drc_practice_blue_cylinder_9'>
        <pose>-2 6 0 0 -0 0</pose>
        <link name='link'>
          <pose>-2 6 0 0 -0 0</pose>
          <velocity>0 0 0 0 -0 0</velocity>
          <acceleration>0 0 0 0 -0 0</acceleration>
          <wrench>0 0 0 0 -0 0</wrench>
        </link>
      </model>
      <model name='ground_plane'>
        <pose>0 0 0 0 -0 0</pose>
        <link name='link'>
          <pose>0 0 0 0 -0 0</pose>
          <velocity>0 0 0 0 -0 0</velocity>
          <acceleration>0 0 0 0 -0 0</acceleration>
          <wrench>0 0 0 0 -0 0</wrench>
        </link>
      </model>
      <model name='jackal'>
        <pose>-0.456368 -0.016323 0.0635 5.29396e-23 -6e-06 3.09303</pose>
        <link name='base_link'>
          <pose>-0.456368 -0.016323 0.0635 5.29396e-23 -6e-06 3.09303</pose>
          <velocity>6.7e-05 1e-05 0.000189 -0.000388 -0.001722 8.8e-05</velocity>
          <acceleration>0 0 0 0 -0 0</acceleration>
          <wrench>0 0 0 0 -0 0</wrench>
        </link>
        <link name='front_left_wheel_link'>
          <pose>-0.59633 -0.197537 0.098 -2.3e-05 -0.05209 3.09303</pose>
          <velocity>4e-06 -7e-06 -0.000116 -1.4e-05 4e-06 2.1e-05</velocity>
          <acceleration>0 0 0 0 -0 0</acceleration>
          <wrench>0 0 0 0 -0 0</wrench>
        </link>
        <link name='front_right_wheel_link'>
          <pose>-0.578098 0.177608 0.098001 2.8e-05 -0.036247 3.09303</pose>
          <velocity>-4.3e-05 -1.6e-05 0.000143 0.000278 -0.000512 0.000212</velocity>
          <acceleration>0 0 0 0 -0 0</acceleration>
          <wrench>0 0 0 0 -0 0</wrench>
        </link>
        <link name='rear_left_wheel_link'>
          <pose>-0.334639 -0.210256 0.098 -4.3451e-19 -0.061796 3.09303</pose>
          <velocity>-1e-05 6e-06 0.000491 -5.9e-05 -9.4e-05 0.000137</velocity>
          <acceleration>0 0 0 0 -0 0</acceleration>
          <wrench>0 0 0 0 -0 0</wrench>
        </link>
        <link name='rear_right_wheel_link'>
          <pose>-0.316407 0.164891 0.098 5e-06 -0.036471 3.09303</pose>
          <velocity>-4.1e-05 6e-05 -4.7e-05 -0.000607 -0.000505 0.000303</velocity>
          <acceleration>0 0 0 0 -0 0</acceleration>
          <wrench>0 0 0 0 -0 0</wrench>
        </link>
      </model>
    </state>
    <gui fullscreen='0'>
      <camera name='user_camera'>
        <pose>5.52968 1.83549 34.6744 0 1.4098 -3.1231</pose>
        <view_controller>orbit</view_controller>
      </camera>
    </gui>
    <model name='jackal'>
      <link name='base_link'>
        <pose>0 0 0 0 -0 0</pose>
        <inertial>
          <pose>0.0229581 0.00183936 0.0861219 0 -0 0</pose>
          <mass>17.966</mass>
          <inertia>
            <ixx>0.396345</ixx>
            <ixy>-0.000437879</ixy>
            <ixz>-0.0225423</ixz>
            <iyy>0.504004</iyy>
            <iyz>-0.000268098</iyz>
            <izz>0.47955</izz>
          </inertia>
        </inertial>
        <collision name='base_link_collision_chassis_link'>
          <pose>0 0 0.092 0 -0 0</pose>
          <geometry>
            <box>
              <size>0.42 0.31 0.184</size>
            </box>
          </geometry>
          <surface>
            <contact>
              <ode/>
            </contact>
            <friction>
              <ode/>
            </friction>
            <bounce/>
          </surface>
          <surface>
            <contact>
              <ode/>
            </contact>
            <friction>
              <ode/>
            </friction>
          </surface>
          <max_contacts>10</max_contacts>
        </collision>
        <collision name='base_link_collision_front_camera'>
          <pose>0.240312 0 0.209718 0 0.5236 0</pose>
          <geometry>
            <box>
              <size>0.0474 0.157 0.036</size>
            </box>
          </geometry>
          <surface>
            <contact>
              <ode/>
            </contact>
            <friction>
              <ode/>
            </friction>
            <bounce/>
          </surface>
          <max_contacts>10</max_contacts>
        </collision>
        <collision name='base_link_collision_front_laser'>
          <pose>0.12 0 0.285 0 -0 0</pose>
          <geometry>
            <box>
              <size>0.105 0.1 0.1</size>
            </box>
          </geometry>
          <surface>
            <contact>
              <ode/>
            </contact>
            <friction>
              <ode/>
            </friction>
            <bounce/>
          </surface>
          <surface>
            <contact>
              <ode/>
            </contact>
            <friction>
              <ode/>
            </friction>
          </surface>
          <max_contacts>10</max_contacts>
        </collision>
        <visual name='base_link_visual_chassis_link'>
          <pose>0 0 -0.0655 1.5708 -5.55112e-17 1.5708</pose>
          <geometry>
            <mesh>
              <scale>1 1 1</scale>
              <uri>/home/master/jackal_navigation/src/jackal/jackal_description/meshes/jackal-base.stl</uri>
            </mesh>
          </geometry>
          <material>
            <script>
              <name>Gazebo/DarkGrey</name>
              <uri>__default__</uri>
            </script>
          </material>
        </visual>
        <visual name='base_link_visual_fenders_link'>
          <pose>0 0 -0.0655 1.5708 -5.55112e-17 1.5708</pose>
          <geometry>
            <mesh>
              <scale>1 1 1</scale>
              <uri>/home/master/jackal_navigation/src/jackal/jackal_description/meshes/jackal-fenders.stl</uri>
            </mesh>
          </geometry>
          <material>
            <script>
              <name>Gazebo/Yellow</name>
              <uri>__default__</uri>
            </script>
          </material>
        </visual>
        <visual name='base_link_visual_front_camera'>
          <pose>0.240312 0 0.209718 -2.0943 4.81635e-05 -1.57071</pose>
          <geometry>
            <mesh>
              <scale>1 1 1</scale>
              <uri>/home/master/jackal_navigation/src/pointgrey_camera_driver/pointgrey_camera_description/meshes/pointgrey_bumblebee2.dae</uri>
            </mesh>
          </geometry>
        </visual>
        <visual name='base_link_visual_front_camera_beam'>
          <pose>0.222 0 0.192 0.5236 4.81635e-05 1.57071</pose>
          <geometry>
            <mesh>
              <scale>0.001 0.001 0.001</scale>
              <uri>/home/master/jackal_navigation/src/jackal/jackal_description/meshes/camera-beam.stl</uri>
            </mesh>
          </geometry>
          <material>
            <script>
              <name>Gazebo/DarkGrey</name>
              <uri>__default__</uri>
            </script>
          </material>
        </visual>
        <visual name='base_link_visual_front_camera_mount'>
          <pose>0.12 0 0.184 1.5707 5.55112e-17 1.5707</pose>
          <geometry>
            <mesh>
              <scale>0.001 0.001 0.001</scale>
              <uri>/home/master/jackal_navigation/src/jackal/jackal_description/meshes/camera-bracket.stl</uri>
            </mesh>
          </geometry>
          <material>
            <script>
              <name>Gazebo/DarkGrey</name>
              <uri>__default__</uri>
            </script>
          </material>
        </visual>
        <visual name='base_link_visual_front_laser'>
          <pose>0.12 0 0.335 0 -0 0</pose>
          <geometry>
            <mesh>
              <scale>1 1 1</scale>
              <uri>/home/master/jackal_navigation/src/LMS1xx/meshes/sick-lms1xx.dae</uri>
            </mesh>
          </geometry>
        </visual>
        <visual name='base_link_visual_front_laser_mount'>
          <pose>0.12 0 0.186 0 -0 0</pose>
          <geometry>
            <mesh>
              <scale>1 1 1</scale>
              <uri>/home/master/jackal_navigation/src/jackal/jackal_description/meshes/sick-lms1xx-bracket.stl</uri>
            </mesh>
          </geometry>
          <material>
            <script>
              <name>Gazebo/DarkGrey</name>
              <uri>__default__</uri>
            </script>
          </material>
        </visual>
        <visual name='base_link_visual_navsat_link'>
          <pose>-0.18 0.126 0.1895 0 -0 0</pose>
          <geometry>
            <cylinder>
              <length>0.016</length>
              <radius>0.026</radius>
            </cylinder>
          </geometry>
          <material>
            <script>
              <name>Gazebo/DarkGrey</name>
              <uri>__default__</uri>
            </script>
          </material>
        </visual>
        <visual name='base_link_visual_rear_bridge'>
          <pose>-0.12 0 0.284 1.5707 5.55112e-17 1.5707</pose>
          <geometry>
            <mesh>
              <scale>1 1 1</scale>
              <uri>/home/master/jackal_navigation/src/jackal/jackal_description/meshes/bridge-plate.stl</uri>
            </mesh>
          </geometry>
        </visual>
        <visual name='base_link_visual_rear_navsat'>
          <pose>-0.12 0 0.284 0 -0 0</pose>
          <geometry>
            <mesh>
              <scale>1 1 1</scale>
              <uri>/home/master/jackal_navigation/src/jackal/jackal_description/meshes/novatel-smart6.stl</uri>
            </mesh>
          </geometry>
        </visual>
        <visual name='base_link_visual_rear_standoff0'>
          <pose>-0.06 0.06 0.234 0 -0 0</pose>
          <geometry>
            <cylinder>
              <length>0.1</length>
              <radius>0.004</radius>
            </cylinder>
          </geometry>
        </visual>
        <visual name='base_link_visual_rear_standoff1'>
          <pose>-0.06 -0.06 0.234 0 -0 0</pose>
          <geometry>
            <cylinder>
              <length>0.1</length>
              <radius>0.004</radius>
            </cylinder>
          </geometry>
        </visual>
        <visual name='base_link_visual_rear_standoff2'>
          <pose>-0.18 0.06 0.234 0 -0 0</pose>
          <geometry>
            <cylinder>
              <length>0.1</length>
              <radius>0.004</radius>
            </cylinder>
          </geometry>
        </visual>
        <visual name='base_link_visual_rear_standoff3'>
          <pose>-0.18 -0.06 0.234 0 -0 0</pose>
          <geometry>
            <cylinder>
              <length>0.1</length>
              <radius>0.004</radius>
            </cylinder>
          </geometry>
        </visual>
        <velocity_decay>
          <linear>0</linear>
          <angular>0</angular>
        </velocity_decay>
        <velocity_decay>
          <linear>0</linear>
          <angular>0</angular>
        </velocity_decay>
        <velocity_decay>
          <linear>0</linear>
          <angular>0</angular>
        </velocity_decay>
        <velocity_decay>
          <linear>0</linear>
          <angular>0</angular>
        </velocity_decay>
        <velocity_decay>
          <linear>0</linear>
          <angular>0</angular>
        </velocity_decay>
        <velocity_decay>
          <linear>0</linear>
          <angular>0</angular>
        </velocity_decay>
        <velocity_decay>
          <linear>0</linear>
          <angular>0</angular>
        </velocity_decay>
        <sensor name='stereo_camera' type='multicamera'>
          <update_rate>20</update_rate>
          <camera name='left'>
            <pose>0 0 0 5.76279e-13 -1.5707 1.5707</pose>
            <horizontal_fov>1.15192</horizontal_fov>
            <image>
              <width>1024</width>
              <height>768</height>
              <format>R8G8B8</format>
            </image>
            <clip>
              <near>0.5</near>
              <far>300</far>
            </clip>
            <noise>
              <type>gaussian</type>
              <mean>0</mean>
              <stddev>0.007</stddev>
            </noise>
          </camera>
          <camera name='right'>
            <pose>0.12 0 0 5.76279e-13 -1.5707 1.5707</pose>
            <horizontal_fov>1.15192</horizontal_fov>
            <image>
              <width>1024</width>
              <height>768</height>
              <format>R8G8B8</format>
            </image>
            <clip>
              <near>0.5</near>
              <far>300</far>
            </clip>
            <noise>
              <type>gaussian</type>
              <mean>0</mean>
              <stddev>0.007</stddev>
            </noise>
          </camera>
          <plugin name='stereo_camera_controller' filename='libgazebo_ros_multicamera.so'>
            <alwaysOn>true</alwaysOn>
            <cameraName>front</cameraName>
            <imageTopicName>image_raw</imageTopicName>
            <cameraInfoTopicName>camera_info</cameraInfoTopicName>
            <frameName>front_camera_optical</frameName>
            <hackBaseline>0.12</hackBaseline>
            <distortionK1>0.0</distortionK1>
            <distortionK2>0.0</distortionK2>
            <distortionK3>0.0</distortionK3>
            <distortionT1>0.0</distortionT1>
            <distortionT2>0.0</distortionT2>
            <robotNamespace>/</robotNamespace>
          </plugin>
          <pose>0.240312 0 0.209718 -2.0944 1.63398e-07 -1.5708</pose>
        </sensor>
        <velocity_decay>
          <linear>0</linear>
          <angular>0</angular>
        </velocity_decay>
        <velocity_decay>
          <linear>0</linear>
          <angular>0</angular>
        </velocity_decay>
        <sensor name='front_laser' type='ray'>
          <visualize>0</visualize>
          <update_rate>50</update_rate>
          <ray>
            <scan>
              <horizontal>
                <samples>720</samples>
                <resolution>1</resolution>
                <min_angle>-2.35619</min_angle>
                <max_angle>2.35619</max_angle>
              </horizontal>
            </scan>
            <range>
              <min>0.1</min>
              <max>30</max>
              <resolution>0.01</resolution>
            </range>
            <noise>
              <type>gaussian</type>
              <mean>0</mean>
              <stddev>0.001</stddev>
            </noise>
          </ray>
          <plugin name='gazebo_ros_laser' filename='libgazebo_ros_laser.so'>
            <topicName>front/scan</topicName>
            <frameName>front_laser</frameName>
            <robotNamespace>/</robotNamespace>
          </plugin>
          <pose>0.12 0 0.335 0 -0 0</pose>
        </sensor>
        <gravity>1</gravity>
        <velocity_decay>
          <linear>0</linear>
          <angular>0</angular>
        </velocity_decay>
        <self_collide>0</self_collide>
        <kinematic>0</kinematic>
      </link>
      <link name='front_left_wheel_link'>
        <pose>0.131 0.187795 0.0345 0 -0 0</pose>
        <inertial>
          <pose>0 0 0 0 -0 0</pose>
          <mass>0.477</mass>
          <inertia>
            <ixx>0.0013</ixx>
            <ixy>0</ixy>
            <ixz>0</ixz>
            <iyy>0.0024</iyy>
            <iyz>0</iyz>
            <izz>0.0013</izz>
          </inertia>
        </inertial>
        <collision name='front_left_wheel_link_collision'>
          <pose>0 0 0 1.5708 -0 0</pose>
          <geometry>
            <cylinder>
              <length>0.04</length>
              <radius>0.098</radius>
            </cylinder>
          </geometry>
          <surface>
            <contact>
              <ode/>
            </contact>
            <friction>
              <ode/>
            </friction>
            <bounce/>
          </surface>
          <max_contacts>10</max_contacts>
        </collision>
        <visual name='front_left_wheel_link_visual'>
          <pose>0 0 0 1.5708 -0 0</pose>
          <geometry>
            <mesh>
              <scale>1 1 1</scale>
              <uri>/home/master/jackal_navigation/src/jackal/jackal_description/meshes/jackal-wheel.stl</uri>
            </mesh>
          </geometry>
          <material>
            <script>
              <name>Gazebo/DarkGrey</name>
              <uri>__default__</uri>
            </script>
          </material>
        </visual>
        <gravity>1</gravity>
        <velocity_decay>
          <linear>0</linear>
          <angular>0</angular>
        </velocity_decay>
        <self_collide>0</self_collide>
        <kinematic>0</kinematic>
      </link>
      <joint name='front_left_wheel' type='revolute'>
        <child>front_left_wheel_link</child>
        <parent>base_link</parent>
        <axis>
          <xyz>0 1 0</xyz>
          <limit>
            <lower>-1e+16</lower>
            <upper>1e+16</upper>
          </limit>
          <dynamics/>
        </axis>
      </joint>
      <link name='front_right_wheel_link'>
        <pose>0.131 -0.187795 0.0345 0 -0 0</pose>
        <inertial>
          <pose>0 0 0 0 -0 0</pose>
          <mass>0.477</mass>
          <inertia>
            <ixx>0.0013</ixx>
            <ixy>0</ixy>
            <ixz>0</ixz>
            <iyy>0.0024</iyy>
            <iyz>0</iyz>
            <izz>0.0013</izz>
          </inertia>
        </inertial>
        <collision name='front_right_wheel_link_collision'>
          <pose>0 0 0 1.5708 -0 0</pose>
          <geometry>
            <cylinder>
              <length>0.04</length>
              <radius>0.098</radius>
            </cylinder>
          </geometry>
          <surface>
            <contact>
              <ode/>
            </contact>
            <friction>
              <ode/>
            </friction>
            <bounce/>
          </surface>
          <max_contacts>10</max_contacts>
        </collision>
        <visual name='front_right_wheel_link_visual'>
          <pose>0 0 0 1.5708 -0 0</pose>
          <geometry>
            <mesh>
              <scale>1 1 1</scale>
              <uri>/home/master/jackal_navigation/src/jackal/jackal_description/meshes/jackal-wheel.stl</uri>
            </mesh>
          </geometry>
          <material>
            <script>
              <name>Gazebo/DarkGrey</name>
              <uri>__default__</uri>
            </script>
          </material>
        </visual>
        <gravity>1</gravity>
        <velocity_decay>
          <linear>0</linear>
          <angular>0</angular>
        </velocity_decay>
        <self_collide>0</self_collide>
        <kinematic>0</kinematic>
      </link>
      <joint name='front_right_wheel' type='revolute'>
        <child>front_right_wheel_link</child>
        <parent>base_link</parent>
        <axis>
          <xyz>0 1 0</xyz>
          <limit>
            <lower>-1e+16</lower>
            <upper>1e+16</upper>
          </limit>
          <dynamics/>
        </axis>
      </joint>
      <link name='rear_left_wheel_link'>
        <pose>-0.131 0.187795 0.0345 0 -0 0</pose>
        <inertial>
          <pose>0 0 0 0 -0 0</pose>
          <mass>0.477</mass>
          <inertia>
            <ixx>0.0013</ixx>
            <ixy>0</ixy>
            <ixz>0</ixz>
            <iyy>0.0024</iyy>
            <iyz>0</iyz>
            <izz>0.0013</izz>
          </inertia>
        </inertial>
        <collision name='rear_left_wheel_link_collision'>
          <pose>0 0 0 1.5708 -0 0</pose>
          <geometry>
            <cylinder>
              <length>0.04</length>
              <radius>0.098</radius>
            </cylinder>
          </geometry>
          <surface>
            <contact>
              <ode/>
            </contact>
            <friction>
              <ode/>
            </friction>
            <bounce/>
          </surface>
          <max_contacts>10</max_contacts>
        </collision>
        <visual name='rear_left_wheel_link_visual'>
          <pose>0 0 0 1.5708 -0 0</pose>
          <geometry>
            <mesh>
              <scale>1 1 1</scale>
              <uri>/home/master/jackal_navigation/src/jackal/jackal_description/meshes/jackal-wheel.stl</uri>
            </mesh>
          </geometry>
          <material>
            <script>
              <name>Gazebo/DarkGrey</name>
              <uri>__default__</uri>
            </script>
          </material>
        </visual>
        <gravity>1</gravity>
        <velocity_decay>
          <linear>0</linear>
          <angular>0</angular>
        </velocity_decay>
        <self_collide>0</self_collide>
        <kinematic>0</kinematic>
      </link>
      <joint name='rear_left_wheel' type='revolute'>
        <child>rear_left_wheel_link</child>
        <parent>base_link</parent>
        <axis>
          <xyz>0 1 0</xyz>
          <limit>
            <lower>-1e+16</lower>
            <upper>1e+16</upper>
          </limit>
          <dynamics/>
        </axis>
      </joint>
      <link name='rear_right_wheel_link'>
        <pose>-0.131 -0.187795 0.0345 0 -0 0</pose>
        <inertial>
          <pose>0 0 0 0 -0 0</pose>
          <mass>0.477</mass>
          <inertia>
            <ixx>0.0013</ixx>
            <ixy>0</ixy>
            <ixz>0</ixz>
            <iyy>0.0024</iyy>
            <iyz>0</iyz>
            <izz>0.0013</izz>
          </inertia>
        </inertial>
        <collision name='rear_right_wheel_link_collision'>
          <pose>0 0 0 1.5708 -0 0</pose>
          <geometry>
            <cylinder>
              <length>0.04</length>
              <radius>0.098</radius>
            </cylinder>
          </geometry>
          <surface>
            <contact>
              <ode/>
            </contact>
            <friction>
              <ode/>
            </friction>
            <bounce/>
          </surface>
          <max_contacts>10</max_contacts>
        </collision>
        <visual name='rear_right_wheel_link_visual'>
          <pose>0 0 0 1.5708 -0 0</pose>
          <geometry>
            <mesh>
              <scale>1 1 1</scale>
              <uri>/home/master/jackal_navigation/src/jackal/jackal_description/meshes/jackal-wheel.stl</uri>
            </mesh>
          </geometry>
          <material>
            <script>
              <name>Gazebo/DarkGrey</name>
              <uri>__default__</uri>
            </script>
          </material>
        </visual>
        <gravity>1</gravity>
        <velocity_decay>
          <linear>0</linear>
          <angular>0</angular>
        </velocity_decay>
        <self_collide>0</self_collide>
        <kinematic>0</kinematic>
      </link>
      <joint name='rear_right_wheel' type='revolute'>
        <child>rear_right_wheel_link</child>
        <parent>base_link</parent>
        <axis>
          <xyz>0 1 0</xyz>
          <limit>
            <lower>-1e+16</lower>
            <upper>1e+16</upper>
          </limit>
          <dynamics/>
        </axis>
      </joint>
      <plugin name='gazebo_ros_control' filename='libgazebo_ros_control.so'>
        <robotNamespace>/</robotNamespace>
      </plugin>
      <plugin name='imu_controller' filename='libhector_gazebo_ros_imu.so'>
        <robotNamespace>/</robotNamespace>
        <updateRate>50.0</updateRate>
        <topicName>imu/data</topicName>
        <accelDrift>0.005 0.005 0.005</accelDrift>
        <accelGaussianNoise>0.005 0.005 0.005</accelGaussianNoise>
        <rateDrift>0.005 0.005 0.005</rateDrift>
        <rateGaussianNoise>0.005 0.005 0.005</rateGaussianNoise>
        <headingDrift>0.005</headingDrift>
        <headingGaussianNoise>0.005</headingGaussianNoise>
        <bodyName>base_link</bodyName>
        <xyzOffset>0 0 0</xyzOffset>
        <rpyOffset>0 -0 0</rpyOffset>
      </plugin>
      <static>0</static>
      <plugin name='gps_controller' filename='libhector_gazebo_ros_gps.so'>
        <updateRate>40</updateRate>
        <robotNamespace>/</robotNamespace>
        <frameId>base_link</frameId>
        <topicName>/navsat/fix</topicName>
        <velocityTopicName>/navsat/vel</velocityTopicName>
        <referenceLatitude>49.9</referenceLatitude>
        <referenceLongitude>8.9</referenceLongitude>
        <referenceHeading>0</referenceHeading>
        <referenceAltitude>0</referenceAltitude>
        <drift>0.0001 0.0001 0.0001</drift>
        <bodyName>base_link</bodyName>
        <xyzOffset>0.18 -0.126 -0.1815</xyzOffset>
        <rpyOffset>0 -0 0</rpyOffset>
      </plugin>
      <pose>0 0 1 0 -0 0</pose>
    </model>
    <model name='drc_practice_blue_cylinder_1'>
      <static>1</static>
      <link name='link'>
        <visual name='visual'>
          <geometry>
            <mesh>
              <uri>model://drc_practice_blue_cylinder/meshes/cylinder.dae</uri>
            </mesh>
          </geometry>
        </visual>
        <collision name='collision'>
          <geometry>
            <mesh>
              <uri>model://drc_practice_blue_cylinder/meshes/cylinder.dae</uri>
            </mesh>
          </geometry>
          <max_contacts>10</max_contacts>
          <surface>
            <bounce/>
            <friction>
              <ode/>
            </friction>
            <contact>
              <ode/>
            </contact>
          </surface>
        </collision>
        <velocity_decay>
          <linear>0</linear>
          <angular>0</angular>
        </velocity_decay>
        <self_collide>0</self_collide>
        <kinematic>0</kinematic>
        <gravity>1</gravity>
      </link>
      <pose>-2 2 0 0 -0 0</pose>
    </model>
    <model name='drc_practice_blue_cylinder_2'>
      <static>1</static>
      <link name='link'>
        <visual name='visual'>
          <geometry>
            <mesh>
              <uri>model://drc_practice_blue_cylinder/meshes/cylinder.dae</uri>
            </mesh>
          </geometry>
        </visual>
        <collision name='collision'>
          <geometry>
            <mesh>
              <uri>model://drc_practice_blue_cylinder/meshes/cylinder.dae</uri>
            </mesh>
          </geometry>
          <max_contacts>10</max_contacts>
          <surface>
            <bounce/>
            <friction>
              <ode/>
            </friction>
            <contact>
              <ode/>
            </contact>
          </surface>
        </collision>
        <velocity_decay>
          <linear>0</linear>
          <angular>0</angular>
        </velocity_decay>
        <self_collide>0</self_collide>
        <kinematic>0</kinematic>
        <gravity>1</gravity>
      </link>
      <pose>-2 -2 0 0 -0 0</pose>
    </model>
    <model name='drc_practice_blue_cylinder_3'>
      <static>1</static>
      <link name='link'>
        <visual name='visual'>
          <geometry>
            <mesh>
              <uri>model://drc_practice_blue_cylinder/meshes/cylinder.dae</uri>
            </mesh>
          </geometry>
        </visual>
        <collision name='collision'>
          <geometry>
            <mesh>
              <uri>model://drc_practice_blue_cylinder/meshes/cylinder.dae</uri>
            </mesh>
          </geometry>
          <max_contacts>10</max_contacts>
          <surface>
            <bounce/>
            <friction>
              <ode/>
            </friction>
            <contact>
              <ode/>
            </contact>
          </surface>
        </collision>
        <velocity_decay>
          <linear>0</linear>
          <angular>0</angular>
        </velocity_decay>
        <self_collide>0</self_collide>
        <kinematic>0</kinematic>
        <gravity>1</gravity>
      </link>
      <pose>-5 -2 0 0 -0 0</pose>
    </model>
    <model name='drc_practice_blue_cylinder_4'>
      <static>1</static>
      <link name='link'>
        <visual name='visual'>
          <geometry>
            <mesh>
              <uri>model://drc_practice_blue_cylinder/meshes/cylinder.dae</uri>
            </mesh>
          </geometry>
        </visual>
        <collision name='collision'>
          <geometry>
            <mesh>
              <uri>model://drc_practice_blue_cylinder/meshes/cylinder.dae</uri>
            </mesh>
          </geometry>
          <max_contacts>10</max_contacts>
          <surface>
            <bounce/>
            <friction>
              <ode/>
            </friction>
            <contact>
              <ode/>
            </contact>
          </surface>
        </collision>
        <velocity_decay>
          <linear>0</linear>
          <angular>0</angular>
        </velocity_decay>
        <self_collide>0</self_collide>
        <kinematic>0</kinematic>
        <gravity>1</gravity>
      </link>
      <pose>-5 2 0 0 -0 0</pose>
    </model>
    <model name='drc_practice_blue_cylinder_5'>
      <static>1</static>
      <link name='link'>
        <visual name='visual'>
          <geometry>
            <mesh>
              <uri>model://drc_practice_blue_cylinder/meshes/cylinder.dae</uri>
            </mesh>
          </geometry>
        </visual>
        <collision name='collision'>
          <geometry>
            <mesh>
              <uri>model://drc_practice_blue_cylinder/meshes/cylinder.dae</uri>
            </mesh>
          </geometry>
          <max_contacts>10</max_contacts>
          <surface>
            <bounce/>
            <friction>
              <ode/>
            </friction>
            <contact>
              <ode/>
            </contact>
          </surface>
        </collision>
        <velocity_decay>
          <linear>0</linear>
          <angular>0</angular>
        </velocity_decay>
        <self_collide>0</self_collide>
        <kinematic>0</kinematic>
        <gravity>1</gravity>
      </link>
      <pose>-8 -2 0 0 -0 0</pose>
    </model>
    <model name='drc_practice_blue_cylinder_6'>
      <static>1</static>
      <link name='link'>
        <visual name='visual'>
          <geometry>
            <mesh>
              <uri>model://drc_practice_blue_cylinder/meshes/cylinder.dae</uri>
            </mesh>
          </geometry>
        </visual>
        <collision name='collision'>
          <geometry>
            <mesh>
              <uri>model://drc_practice_blue_cylinder/meshes/cylinder.dae</uri>
            </mesh>
          </geometry>
          <max_contacts>10</max_contacts>
          <surface>
            <bounce/>
            <friction>
              <ode/>
            </friction>
            <contact>
              <ode/>
            </contact>
          </surface>
        </collision>
        <velocity_decay>
          <linear>0</linear>
          <angular>0</angular>
        </velocity_decay>
        <self_collide>0</self_collide>
        <kinematic>0</kinematic>
        <gravity>1</gravity>
      </link>
      <pose>-8 2 0 0 -0 0</pose>
    </model>
    <model name='drc_practice_blue_cylinder_7'>
      <static>1</static>
      <link name='link'>
        <visual name='visual'>
          <geometry>
            <mesh>
              <uri>model://drc_practice_blue_cylinder/meshes/cylinder.dae</uri>
            </mesh>
          </geometry>
        </visual>
        <collision name='collision'>
          <geometry>
            <mesh>
              <uri>model://drc_practice_blue_cylinder/meshes/cylinder.dae</uri>
            </mesh>
          </geometry>
          <max_contacts>10</max_contacts>
          <surface>
            <bounce/>
            <friction>
              <ode/>
            </friction>
            <contact>
              <ode/>
            </contact>
          </surface>
        </collision>
        <velocity_decay>
          <linear>0</linear>
          <angular>0</angular>
        </velocity_decay>
        <self_collide>0</self_collide>
        <kinematic>0</kinematic>
        <gravity>1</gravity>
      </link>
      <pose>-8 6 0 0 -0 0</pose>
    </model>
    <model name='drc_practice_blue_cylinder_8'>
      <static>1</static>
      <link name='link'>
        <visual name='visual'>
          <geometry>
            <mesh>
              <uri>model://drc_practice_blue_cylinder/meshes/cylinder.dae</uri>
            </mesh>
          </geometry>
        </visual>
        <collision name='collision'>
          <geometry>
            <mesh>
              <uri>model://drc_practice_blue_cylinder/meshes/cylinder.dae</uri>
            </mesh>
          </geometry>
          <max_contacts>10</max_contacts>
          <surface>
            <bounce/>
            <friction>
              <ode/>
            </friction>
            <contact>
              <ode/>
            </contact>
          </surface>
        </collision>
        <velocity_decay>
          <linear>0</linear>
          <angular>0</angular>
        </velocity_decay>
        <self_collide>0</self_collide>
        <kinematic>0</kinematic>
        <gravity>1</gravity>
      </link>
      <pose>-5 6 0 0 -0 0</pose>
    </model>
    <model name='drc_practice_blue_cylinder_9'>
      <static>1</static>
      <link name='link'>
        <visual name='visual'>
          <geometry>
            <mesh>
              <uri>model://drc_practice_blue_cylinder/meshes/cylinder.dae</uri>
            </mesh>
          </geometry>
        </visual>
        <collision name='collision'>
          <geometry>
            <mesh>
              <uri>model://drc_practice_blue_cylinder/meshes/cylinder.dae</uri>
            </mesh>
          </geometry>
          <max_contacts>10</max_contacts>
          <surface>
            <bounce/>
            <friction>
              <ode/>
            </friction>
            <contact>
              <ode/>
            </contact>
          </surface>
        </collision>
        <velocity_decay>
          <linear>0</linear>
          <angular>0</angular>
        </velocity_decay>
        <self_collide>0</self_collide>
        <kinematic>0</kinematic>
        <gravity>1</gravity>
      </link>
      <pose>-2 6 0 0 -0 0</pose>
    </model>
  </world>
</sdf>
